SMTPAuthenticationError
smtplib.SMTPAuthenticationError: (535, b'5.7.8 Username and Password not accepted. For more information, go to\n5.7.8  https://support.google.com/mail/?p=BadCredentials d9443c01a7336-219dca02b77sm138491105ad.242 - gsmtp')

Traceback (most recent call last)
File "/home/runner/Website-Editor/.pythonlibs/lib/python3.12/site-packages/flask/app.py", line 1536, in __call__
return self.wsgi_app(environ, start_response)
       ^^^^^^^^^^^^^^^^^^^^^^^^^^^^^^^^^^^^^^
File "/home/runner/Website-Editor/.pythonlibs/lib/python3.12/site-packages/flask/app.py", line 1514, in wsgi_app
response = self.handle_exception(e)
           ^^^^^^^^^^^^^^^^^^^^^^^^
File "/home/runner/Website-Editor/.pythonlibs/lib/python3.12/site-packages/flask/app.py", line 1511, in wsgi_app
response = self.full_dispatch_request()
           ^^^^^^^^^^^^^^^^^^^^^^^^^^^^
File "/home/runner/Website-Editor/.pythonlibs/lib/python3.12/site-packages/flask/app.py", line 919, in full_dispatch_request
rv = self.handle_user_exception(e)
     ^^^^^^^^^^^^^^^^^^^^^^^^^^^^^
File "/home/runner/Website-Editor/.pythonlibs/lib/python3.12/site-packages/flask/app.py", line 917, in full_dispatch_request
rv = self.dispatch_request()
     ^^^^^^^^^^^^^^^^^^^^^^^
File "/home/runner/Website-Editor/.pythonlibs/lib/python3.12/site-packages/flask/app.py", line 902, in dispatch_request
return self.ensure_sync(self.view_functions[rule.endpoint])(**view_args)  # type: ignore[no-any-return]
       ^^^^^^^^^^^^^^^^^^^^^^^^^^^^^^^^^^^^^^^^^^^^^^^^^^^^^^^^^^^^^^^^^
File "/home/runner/Website-Editor/app.py", line 431, in register
mail.send(msg)
^^^^^^^^^^^^^^
File "/home/runner/Website-Editor/.pythonlibs/lib/python3.12/site-packages/flask_mail/__init__.py", line 539, in send
with self.connect() as connection:
     ^^^^^^^^^^^^^^
File "/home/runner/Website-Editor/.pythonlibs/lib/python3.12/site-packages/flask_mail/__init__.py", line 127, in __enter__
self.host = self.configure_host()
            ^^^^^^^^^^^^^^^^^^^^^
File "/home/runner/Website-Editor/.pythonlibs/lib/python3.12/site-packages/flask_mail/__init__.py", line 152, in configure_host
host.login(self.mail.username, self.mail.password)
^^^^^^^^^^^^^^^^^^^^^^^^^^^^^^^^^^^^^^^^^^^^^^^^^^
File "/nix/store/nb21sc3npfc8gvazwnrjxpvb5d48jysx-python3-3.12.7/lib/python3.12/smtplib.py", line 750, in login
raise last_exception
^^^^^^^^^^^^^^^^^^^^
File "/nix/store/nb21sc3npfc8gvazwnrjxpvb5d48jysx-python3-3.12.7/lib/python3.12/smtplib.py", line 739, in login
(code, resp) = self.auth(
               ^^^^^^^^^^^^^^^^^^^^^^^^^^^^^
File "/nix/store/nb21sc3npfc8gvazwnrjxpvb5d48jysx-python3-3.12.7/lib/python3.12/smtplib.py", line 662, in auth
raise SMTPAuthenticationError(code, resp)
^^^^^^^^^^^^^^^^^^^^^^^^^^^^^^^^^^^^^^^^^
smtplib.SMTPAuthenticationError: (535, b'5.7.8 Username and Password not accepted. For more information, go to\n5.7.8 https://support.google.com/mail/?p=BadCredentials d9443c01a7336-219dca02b77sm138491105ad.242 - gsmtp')
The debugger caught an exception in your WSGI application. You can now look at the traceback which led to the error.
To switch between the interactive traceback and the plaintext one, you can click on the "Traceback" headline. From the text traceback you can also create a paste of it.

Brought to you by DON'T PANIC, your friendly Werkzeug powered traceback interpreter.